<?xml version="1.0" ?>
<sdf version="1.4">

  <model name="dustbin">
    <static>false</static>
    
    <!-- Base Link -->
    <link name="base_link">
      <inertial>
        <pose>0 0 0.3 0 0 0</pose>
        <mass>2.0</mass>
        <inertia>
          <ixx>0.1</ixx>
          <ixy>0</ixy>
          <ixz>0</ixz>
          <iyy>0.1</iyy>
          <iyz>0</iyz>
          <izz>0.1</izz>
        </inertia>
      </inertial>

      <collision name="collision">
        <pose>0 0 0.3 0 0 0</pose>
        <geometry>
          <cylinder>
            <radius>0.2</radius>
            <length>0.6</length>
          </cylinder>
        </geometry>
        <surface>
          <friction>
            <ode>
              <mu>0.2</mu>
              <mu2>0.2</mu2>
            </ode>
          </friction>
        </surface>
      </collision>

      <visual name="visual">
        <pose>0 0 0.3 0 0 0</pose>
        <geometry>
          <cylinder>
            <radius>0.2</radius>
            <length>0.6</length>
          </cylinder>
        </geometry>
        <material>
          <script>
            <uri>file://media/materials/scripts/gazebo.material</uri>
            <name>Gazebo/Blue</name>
          </script>
        </material>
      </visual>
    </link>

    <!-- Lid Link -->
    
     <link name="lid">
        <pose>0 0.2 0.6 0 0 0</pose>
        <inertial>
            <mass>0.5</mass>
            <inertia>
            <ixx>0.01</ixx>
            <ixy>0</ixy>
            <ixz>0</ixz>
            <iyy>0.01</iyy>
            <iyz>0</iyz>
            <izz>0.01</izz>
            </inertia>
        </inertial>

      <collision name="collision">
        <geometry>
          <cylinder>
            <radius>0.21</radius>
            <length>0.02</length>
          </cylinder>
        </geometry>
        <surface>
          <friction>
            <ode>
              <mu>0.2</mu>
              <mu2>0.2</mu2>
            </ode>
          </friction>
        </surface>
      </collision>

      <visual name="visual">
        <geometry>
          <cylinder>
            <radius>0.21</radius>
            <length>0.02</length>
          </cylinder>
        </geometry>
        <material>
          <script>
            <uri>file://media/materials/scripts/gazebo.material</uri>
            <name>Gazebo/Grey</name>
          </script>
        </material>
      </visual>
    </link>

    <!-- Hinge Joint -->
    <joint name="lid_joint" type="revolute">
      <parent>base_link</parent>
      <child>lid</child>
      <pose>0 0 0 0 0 0</pose>
      <axis>
        <xyz>0 1 0</xyz>
        <limit>
          <lower>0</lower>
          <upper>1.57</upper>
          <effort>10</effort>
          <velocity>1.0</velocity>
        </limit>
        <dynamics>
          <damping>0.5</damping>
          <friction>0.1</friction>
        </dynamics>
      </axis>
    </joint>
  </model>
</sdf>